<?xml version="1.0" ?>
<!-- =================================================================================== -->
<!-- |    This document was autogenerated by xacro from spider.xacro                   | -->
<!-- |    EDITING THIS FILE BY HAND IS NOT RECOMMENDED                                 | -->
<!-- =================================================================================== -->
<!-- Octapod -->
<robot name="spider" xmlns:xacro="http://www.ros.org/wiki/xacro">
  <!-- Space btw top of beam and the each joint -->
  <!-- ros_control plugin -->
  <gazebo>
    <plugin filename="libgazebo_ros_control.so" name="gazebo_ros_control">
      <robotNamespace>/spider</robotNamespace>
      <robotSimType>gazebo_ros_control/DefaultRobotHWSim</robotSimType>
    </plugin>
  </gazebo>
  <plugin filename="libgazebo_ros_joint_state_publisher.so" name="joint_state_publisher">
    <robotNamespace>spider</robotNamespace>
    <jointName>
        joint_1_1,joint_1_2,joint_1_3,joint_2_1,joint_2_2,joint_2_3,joint_3_1,joint_3_2,joint_3_3,joint_4_1,joint_4_2,joint_4_3,joint_5_1,joint_5_2,joint_5_3,joint_6_1,joint_6_2,joint_6_3,joint_7_1,joint_7_2,joint_7_3,joint_8_1,joint_8_2,joint_8_3
    </jointName>
    <updateRate>100</updateRate>
    <alwaysOn>true</alwaysOn>
  </plugin>
  <!-- chassis -->
  <gazebo reference="chassis">
    <material>Gazebo/Orange</material>
  </gazebo>
  <!-- Link1_1 -->
  <gazebo reference="left_torso_1_1">
    <mu1>0.2</mu1>
    <mu2>0.2</mu2>
    <material>Gazebo/Black</material>
  </gazebo>
  <!-- Link1_2 -->
  <gazebo reference="left_torso_1_2">
    <mu1>0.2</mu1>
    <mu2>0.2</mu2>
    <material>Gazebo/Black</material>
  </gazebo>
  <!-- Link1_3 -->
  <gazebo reference="left_torso_1_3">
    <mu1>0.2</mu1>
    <mu2>0.2</mu2>
    <material>Gazebo/Black</material>
  </gazebo>
  <!-- Link2_1 -->
  <gazebo reference="left_torso_2_1">
    <mu1>0.2</mu1>
    <mu2>0.2</mu2>
    <material>Gazebo/Black</material>
  </gazebo>
  <!-- Link2_2 -->
  <gazebo reference="left_torso_2_2">
    <mu1>0.2</mu1>
    <mu2>0.2</mu2>
    <material>Gazebo/Black</material>
  </gazebo>
  <!-- Link2_3 -->
  <gazebo reference="left_torso_2_3">
    <mu1>0.2</mu1>
    <mu2>0.2</mu2>
    <material>Gazebo/Black</material>
  </gazebo>
  <!-- Link3_1 -->
  <gazebo reference="left_torso_3_1">
    <mu1>0.2</mu1>
    <mu2>0.2</mu2>
    <material>Gazebo/Black</material>
  </gazebo>
  <!-- Link3_2 -->
  <gazebo reference="left_torso_3_2">
    <mu1>0.2</mu1>
    <mu2>0.2</mu2>
    <material>Gazebo/Black</material>
  </gazebo>
  <!-- Link3_3 -->
  <gazebo reference="left_torso_3_3">
    <mu1>0.2</mu1>
    <mu2>0.2</mu2>
    <material>Gazebo/Black</material>
  </gazebo>
  <!-- Link4_1 -->
  <gazebo reference="left_torso_4_1">
    <mu1>0.2</mu1>
    <mu2>0.2</mu2>
    <material>Gazebo/Black</material>
  </gazebo>
  <!-- Link4_2 -->
  <gazebo reference="left_torso_4_2">
    <mu1>0.2</mu1>
    <mu2>0.2</mu2>
    <material>Gazebo/Black</material>
  </gazebo>
  <!-- Link4_3 -->
  <gazebo reference="left_torso_4_3">
    <mu1>0.2</mu1>
    <mu2>0.2</mu2>
    <material>Gazebo/Black</material>
  </gazebo>
  <!-- Link5_1 -->
  <gazebo reference="right_torso_1_1">
    <mu1>0.2</mu1>
    <mu2>0.2</mu2>
    <material>Gazebo/Black</material>
  </gazebo>
  <!-- Link5_2 -->
  <gazebo reference="right_torso_1_2">
    <mu1>0.2</mu1>
    <mu2>0.2</mu2>
    <material>Gazebo/Black</material>
  </gazebo>
  <!-- camera_link -->
  <gazebo reference="camera_link">
    <mu1>0.2</mu1>
    <mu2>0.2</mu2>
    <material>Gazebo/Red</material>
  </gazebo>
  <!-- Link5_3 -->
  <gazebo reference="right_torso_1_3">
    <mu1>0.2</mu1>
    <mu2>0.2</mu2>
    <material>Gazebo/Black</material>
  </gazebo>
  <!-- Link6_1 -->
  <gazebo reference="right_torso_2_1">
    <mu1>0.2</mu1>
    <mu2>0.2</mu2>
    <material>Gazebo/Black</material>
  </gazebo>
  <!-- Link6_2 -->
  <gazebo reference="right_torso_2_2">
    <mu1>0.2</mu1>
    <mu2>0.2</mu2>
    <material>Gazebo/Black</material>
  </gazebo>
  <!-- Link6_3 -->
  <gazebo reference="right_torso_2_3">
    <mu1>0.2</mu1>
    <mu2>0.2</mu2>
    <material>Gazebo/Black</material>
  </gazebo>
  <!-- Link7_1 -->
  <gazebo reference="right_torso_3_1">
    <mu1>0.2</mu1>
    <mu2>0.2</mu2>
    <material>Gazebo/Black</material>
  </gazebo>
  <!-- Link7_2 -->
  <gazebo reference="right_torso_3_2">
    <mu1>0.2</mu1>
    <mu2>0.2</mu2>
    <material>Gazebo/Black</material>
  </gazebo>
  <!-- Link7_3 -->
  <gazebo reference="right_torso_3_3">
    <mu1>0.2</mu1>
    <mu2>0.2</mu2>
    <material>Gazebo/Black</material>
  </gazebo>
  <!-- Link8_1 -->
  <gazebo reference="right_torso_4_1">
    <mu1>0.2</mu1>
    <mu2>0.2</mu2>
    <material>Gazebo/Black</material>
  </gazebo>
  <!-- Link8_2 -->
  <gazebo reference="right_torso_4_2">
    <mu1>0.2</mu1>
    <mu2>0.2</mu2>
    <material>Gazebo/Black</material>
  </gazebo>
  <!-- Link8_3 -->
  <gazebo reference="right_torso_4_3">
    <mu1>0.2</mu1>
    <mu2>0.2</mu2>
    <material>Gazebo/Black</material>
  </gazebo>
  <material name="black">
    <color rgba="0.0 0.0 0.0 1.0"/>
  </material>
  <material name="blue">
    <color rgba="0.0 0.0 0.8 1.0"/>
  </material>
  <material name="green">
    <color rgba="0.0 0.8 0.0 1.0"/>
  </material>
  <material name="grey">
    <color rgba="0.2 0.2 0.2 1.0"/>
  </material>
  <material name="orange">
    <color rgba="1.0 0.423529411765 0.0392156862745 1.0"/>
  </material>
  <material name="brown">
    <color rgba="0.870588235294 0.811764705882 0.764705882353 1.0"/>
  </material>
  <material name="red">
    <color rgba="0.8 0.0 0.0 1.0"/>
  </material>
  <material name="white">
    <color rgba="1.0 1.0 1.0 1.0"/>
  </material>
  <!-- chassis -->
  <link name="chassis">
    <collision>
      <origin rpy="0 0 0" xyz="0 0 1.5"/>
      <geometry>
        <cylinder length="3" radius="5"/>
      </geometry>
    </collision>
    <visual>
      <origin rpy="0 0 0" xyz="0 0 1.5"/>
      <geometry>
        <cylinder length="3" radius="5"/>
        <mesh filename="package://spider_description/meshes/chassis_upper.dae"/>
      </geometry>
      <material name="orange"/>
    </visual>
    <inertial>
      <origin rpy="0 0 0" xyz="0 0 1.5"/>
      <mass value="4"/>
      <inertia ixx="16.0" ixy="0.0" ixz="0.0" iyy="16.0" iyz="0.0" izz="11.0"/>
    </inertial>
  </link>
  <joint name="joint_1_1" type="revolute">
    <parent link="chassis"/>
    <child link="left_torso_1_1"/>
    <origin rpy="0 0 0" xyz="0 5 3"/>
    <axis xyz="0 1 0"/>
    <dynamics damping="0.7" friction="0.0"/>
    <limit effort="30" lower="-2.2" upper="0.7" velocity="1.0"/>
    <safety_controller k_position="15" k_velocity="10" soft_lower_limit="-2.0" soft_upper_limit="0.5"/>
  </joint>
  <!-- left_torso_1_1 -->
  <link name="left_torso_1_1">
    <collision>
      <origin rpy="0 0 0" xyz="0 0 4"/>
      <geometry>
        <cylinder length="4" radius="1"/>
      </geometry>
    </collision>
    <visual>
      <origin rpy="0 0 0" xyz="0 0 4"/>
      <geometry>
        <cylinder length="4" radius="1"/>
      </geometry>
      <material name="black"/>
    </visual>
    <inertial>
      <origin rpy="0 0 0" xyz="0 0 4"/>
      <mass value="1"/>
      <inertia ixx="3.5" ixy="0.0" ixz="0.0" iyy="3.5" iyz="0.0" izz="3.0"/>
    </inertial>
  </link>
  <joint name="joint_1_2" type="revolute">
    <parent link="left_torso_1_1"/>
    <child link="left_torso_1_2"/>
    <origin rpy="0 0 0" xyz="0 0 4"/>
    <axis xyz="0 1 0"/>
    <dynamics damping="0.7" friction="0.0"/>
    <limit effort="30" lower="-2.2" upper="0.7" velocity="1.0"/>
    <safety_controller k_position="15" k_velocity="10" soft_lower_limit="-2.0" soft_upper_limit="0.5"/>
  </joint>
  <!-- left_torso_1_2-->
  <link name="left_torso_1_2">
    <collision>
      <origin rpy="0 0 0" xyz="0 0 4"/>
      <geometry>
        <cylinder length="4" radius="1"/>
      </geometry>
    </collision>
    <visual>
      <origin rpy="0 0 0" xyz="0 0 4"/>
      <geometry>
        <cylinder length="4" radius="1"/>
      </geometry>
      <material name="black"/>
    </visual>
    <inertial>
      <origin rpy="0 0 0" xyz="0 0 4"/>
      <mass value="1"/>
      <inertia ixx="3.5" ixy="0.0" ixz="0.0" iyy="3.5" iyz="0.0" izz="3.0"/>
    </inertial>
  </link>
  <joint name="joint_1_3" type="revolute">
    <parent link="left_torso_1_2"/>
    <child link="left_torso_1_3"/>
    <origin rpy="0 0 0" xyz="0 0 4"/>
    <axis xyz="0 1 0"/>
    <dynamics damping="0.7" friction="0.0"/>
    <limit effort="30" lower="-2.2" upper="0.7" velocity="1.0"/>
    <safety_controller k_position="15" k_velocity="10" soft_lower_limit="-2.0" soft_upper_limit="0.5"/>
  </joint>
  <!-- left_torso_1_3 -->
  <link name="left_torso_1_3">
    <collision>
      <origin rpy="0 0 0" xyz="0 0 6"/>
      <geometry>
        <cylinder length="6" radius="1"/>
      </geometry>
    </collision>
    <visual>
      <origin rpy="0 0 0" xyz="0 0 6"/>
      <geometry>
        <cylinder length="6" radius="1"/>
      </geometry>
      <material name="black"/>
    </visual>
    <inertial>
      <origin rpy="0 0 0" xyz="0 0 6"/>
      <mass value="1"/>
      <inertia ixx="4.5" ixy="0.0" ixz="0.0" iyy="4.5" iyz="0.0" izz="3.0"/>
    </inertial>
  </link>
  <joint name="joint_2_1" type="revolute">
    <parent link="chassis"/>
    <child link="left_torso_2_1"/>
    <origin rpy="0 0 0" xyz="-3.535 3.535 3"/>
    <axis xyz="0 1 0"/>
    <dynamics damping="0.7" friction="0.0"/>
    <limit effort="30" lower="-2.2" upper="0.7" velocity="1.0"/>
    <safety_controller k_position="15" k_velocity="10" soft_lower_limit="-2.0" soft_upper_limit="0.5"/>
  </joint>
  <!-- Camera -->
  <link name="left_torso_2_1">
    <collision>
      <origin rpy="0 0 0" xyz="0 0 4"/>
      <geometry>
        <cylinder length="4" radius="1"/>
      </geometry>
    </collision>
    <visual>
      <origin rpy="0 0 0" xyz="0 0 4"/>
      <geometry>
        <cylinder length="4" radius="1"/>
      </geometry>
      <material name="black"/>
    </visual>
    <inertial>
      <origin rpy="0 0 0" xyz="0 0 4"/>
      <mass value="1"/>
      <inertia ixx="3.5" ixy="0.0" ixz="0.0" iyy="3.5" iyz="0.0" izz="3.0"/>
    </inertial>
  </link>
  <joint name="joint_2_2" type="revolute">
    <parent link="left_torso_2_1"/>
    <child link="left_torso_2_2"/>
    <origin rpy="0 0 0" xyz="0 0 4"/>
    <axis xyz="0 1 0"/>
    <dynamics damping="0.7" friction="0.0"/>
    <limit effort="30" lower="-2.2" upper="0.7" velocity="1.0"/>
    <safety_controller k_position="15" k_velocity="10" soft_lower_limit="-2.0" soft_upper_limit="0.5"/>
  </joint>
  <!--left torso link 2_2-->
  <link name="left_torso_2_2">
    <collision>
      <origin rpy="0 0 0" xyz="0 0 4"/>
      <geometry>
        <cylinder length="4" radius="1"/>
      </geometry>
    </collision>
    <visual>
      <origin rpy="0 0 0" xyz="0 0 4"/>
      <geometry>
        <cylinder length="4" radius="1"/>
      </geometry>
      <material name="black"/>
    </visual>
    <inertial>
      <origin rpy="0 0 0" xyz="0 0 4"/>
      <mass value="1"/>
      <inertia ixx="3.5" ixy="0.0" ixz="0.0" iyy="3.5" iyz="0.0" izz="3.0"/>
    </inertial>
  </link>
  <joint name="joint_2_3" type="revolute">
    <parent link="left_torso_2_2"/>
    <child link="left_torso_2_3"/>
    <origin rpy="0 0 0" xyz="0 0 4"/>
    <axis xyz="0 1 0"/>
    <dynamics damping="0.7" friction="0.0"/>
    <limit effort="30" lower="-2.2" upper="0.7" velocity="1.0"/>
    <safety_controller k_position="15" k_velocity="10" soft_lower_limit="-2.0" soft_upper_limit="0.5"/>
  </joint>
  <!--left torso link 2_3-->
  <link name="left_torso_2_3">
    <collision>
      <origin rpy="0 0 0" xyz="0 0 6"/>
      <geometry>
        <cylinder length="6" radius="1"/>
      </geometry>
    </collision>
    <visual>
      <origin rpy="0 0 0" xyz="0 0 6"/>
      <geometry>
        <cylinder length="6" radius="1"/>
      </geometry>
      <material name="black"/>
    </visual>
    <inertial>
      <origin rpy="0 0 0" xyz="0 0 6"/>
      <mass value="1"/>
      <inertia ixx="4.5" ixy="0.0" ixz="0.0" iyy="4.5" iyz="0.0" izz="3.0"/>
    </inertial>
  </link>
  <joint name="joint_3_1" type="revolute">
    <parent link="chassis"/>
    <child link="left_torso_3_1"/>
    <origin rpy="0 0 0" xyz="-5 0 3"/>
    <axis xyz="0 1 0"/>
    <dynamics damping="0.7" friction="0.0"/>
    <limit effort="30" lower="-2.2" upper="0.7" velocity="1.0"/>
    <safety_controller k_position="15" k_velocity="10" soft_lower_limit="-2.0" soft_upper_limit="0.5"/>
  </joint>
  <!--left torso link 3_1-->
  <link name="left_torso_3_1">
    <collision>
      <origin rpy="0 0 0" xyz="0 0 4"/>
      <geometry>
        <cylinder length="4" radius="1"/>
      </geometry>
    </collision>
    <visual>
      <origin rpy="0 0 0" xyz="0 0 4"/>
      <geometry>
        <cylinder length="4" radius="1"/>
      </geometry>
      <material name="black"/>
    </visual>
    <inertial>
      <origin rpy="0 0 0" xyz="0 0 4"/>
      <mass value="1"/>
      <inertia ixx="3.5" ixy="0.0" ixz="0.0" iyy="3.5" iyz="0.0" izz="3.0"/>
    </inertial>
  </link>
  <joint name="joint_3_2" type="revolute">
    <parent link="left_torso_3_1"/>
    <child link="left_torso_3_2"/>
    <origin rpy="0 0 0" xyz="0 0 4"/>
    <axis xyz="0 1 0"/>
    <dynamics damping="0.7" friction="0.0"/>
    <limit effort="30" lower="-2.2" upper="0.7" velocity="1.0"/>
    <safety_controller k_position="15" k_velocity="10" soft_lower_limit="-2.0" soft_upper_limit="0.5"/>
  </joint>
  <link name="left_torso_3_2">
    <collision>
      <origin rpy="0 0 0" xyz="0 0 4"/>
      <geometry>
        <cylinder length="4" radius="1"/>
      </geometry>
    </collision>
    <visual>
      <origin rpy="0 0 0" xyz="0 0 4"/>
      <geometry>
        <cylinder length="4" radius="1"/>
      </geometry>
      <material name="black"/>
    </visual>
    <inertial>
      <origin rpy="0 0 0" xyz="0 0 4"/>
      <mass value="1"/>
      <inertia ixx="3.5" ixy="0.0" ixz="0.0" iyy="3.5" iyz="0.0" izz="3.0"/>
    </inertial>
  </link>
  <joint name="joint_3_3" type="revolute">
    <parent link="left_torso_3_2"/>
    <child link="left_torso_3_3"/>
    <origin rpy="0 0 0" xyz="0 0 4"/>
    <axis xyz="0 1 0"/>
    <dynamics damping="0.7" friction="0.0"/>
    <limit effort="30" lower="-2.2" upper="0.7" velocity="1.0"/>
    <safety_controller k_position="15" k_velocity="10" soft_lower_limit="-2.0" soft_upper_limit="0.5"/>
  </joint>
  <link name="left_torso_3_3">
    <collision>
      <origin rpy="0 0 0" xyz="0 0 6"/>
      <geometry>
        <cylinder length="6" radius="1"/>
      </geometry>
    </collision>
    <visual>
      <origin rpy="0 0 0" xyz="0 0 6"/>
      <geometry>
        <cylinder length="6" radius="1"/>
      </geometry>
      <material name="black"/>
    </visual>
    <inertial>
      <origin rpy="0 0 0" xyz="0 0 6"/>
      <mass value="1"/>
      <inertia ixx="4.5" ixy="0.0" ixz="0.0" iyy="4.5" iyz="0.0" izz="3.0"/>
    </inertial>
  </link>
  <!-- left torso link 4-->
  <joint name="joint_4_1" type="revolute">
    <parent link="chassis"/>
    <child link="left_torso_4_1"/>
    <origin rpy="0 0 0" xyz="-3.535 -3.535 4"/>
    <axis xyz="0 1 0"/>
    <dynamics damping="0.7" friction="0.0"/>
    <limit effort="30" lower="-2.2" upper="0.7" velocity="1.0"/>
    <safety_controller k_position="15" k_velocity="10" soft_lower_limit="-2.0" soft_upper_limit="0.5"/>
  </joint>
  <link name="left_torso_4_1">
    <collision>
      <origin rpy="0 0 0" xyz="0 0 4"/>
      <geometry>
        <cylinder length="4" radius="1"/>
      </geometry>
    </collision>
    <visual>
      <origin rpy="0 0 0" xyz="0 0 4"/>
      <geometry>
        <cylinder length="4" radius="1"/>
      </geometry>
      <material name="black"/>
    </visual>
    <inertial>
      <origin rpy="0 0 0" xyz="0 0 4"/>
      <mass value="1"/>
      <inertia ixx="3.5" ixy="0.0" ixz="0.0" iyy="3.5" iyz="0.0" izz="3.0"/>
    </inertial>
  </link>
  <joint name="joint_4_2" type="revolute">
    <parent link="left_torso_4_1"/>
    <child link="left_torso_4_2"/>
    <origin rpy="0 0 0" xyz="0 0 4"/>
    <axis xyz="0 1 0"/>
    <dynamics damping="0.7" friction="0.0"/>
    <limit effort="30" lower="-2.2" upper="0.7" velocity="1.0"/>
    <safety_controller k_position="15" k_velocity="10" soft_lower_limit="-2.0" soft_upper_limit="0.5"/>
  </joint>
  <link name="left_torso_4_2">
    <collision>
      <origin rpy="0 0 0" xyz="0 0 4"/>
      <geometry>
        <cylinder length="4" radius="1"/>
      </geometry>
    </collision>
    <visual>
      <origin rpy="0 0 0" xyz="0 0 4"/>
      <geometry>
        <cylinder length="4" radius="1"/>
      </geometry>
      <material name="black"/>
    </visual>
    <inertial>
      <origin rpy="0 0 0" xyz="0 0 4"/>
      <mass value="1"/>
      <inertia ixx="3.5" ixy="0.0" ixz="0.0" iyy="3.5" iyz="0.0" izz="3.0"/>
    </inertial>
  </link>
  <joint name="joint_4_3" type="revolute">
    <parent link="left_torso_4_2"/>
    <child link="left_torso_4_3"/>
    <origin rpy="0 0 0" xyz="0 0 4"/>
    <axis xyz="0 1 0"/>
    <dynamics damping="0.7" friction="0.0"/>
    <limit effort="30" lower="-2.2" upper="0.7" velocity="1.0"/>
    <safety_controller k_position="15" k_velocity="10" soft_lower_limit="-2.0" soft_upper_limit="0.5"/>
  </joint>
  <link name="left_torso_4_3">
    <collision>
      <origin rpy="0 0 0" xyz="0 0 6"/>
      <geometry>
        <cylinder length="6" radius="1"/>
      </geometry>
    </collision>
    <visual>
      <origin rpy="0 0 0" xyz="0 0 6"/>
      <geometry>
        <cylinder length="6" radius="1"/>
      </geometry>
      <material name="black"/>
    </visual>
    <inertial>
      <origin rpy="0 0 0" xyz="0 0 6"/>
      <mass value="1"/>
      <inertia ixx="4.5" ixy="0.0" ixz="0.0" iyy="4.5" iyz="0.0" izz="3.0"/>
    </inertial>
  </link>
  <joint name="joint_5_1" type="revolute">
    <parent link="chassis"/>
    <child link="right_torso_1_1"/>
    <origin rpy="0 0 0" xyz="0 -5 4"/>
    <axis xyz="0 1 0"/>
    <dynamics damping="0.7" friction="0.0"/>
    <limit effort="30" lower="-2.2" upper="0.7" velocity="1.0"/>
    <safety_controller k_position="15" k_velocity="10" soft_lower_limit="-2.0" soft_upper_limit="0.5"/>
  </joint>
  <link name="right_torso_1_1">
    <collision>
      <origin rpy="0 0 0" xyz="0 0 4"/>
      <geometry>
        <cylinder length="4" radius="1"/>
      </geometry>
    </collision>
    <visual>
      <origin rpy="0 0 0" xyz="0 0 4"/>
      <geometry>
        <cylinder length="4" radius="1"/>
      </geometry>
      <material name="black"/>
    </visual>
    <inertial>
      <origin rpy="0 0 0" xyz="0 0 4"/>
      <mass value="1"/>
      <inertia ixx="3.5" ixy="0.0" ixz="0.0" iyy="3.5" iyz="0.0" izz="3.0"/>
    </inertial>
  </link>
  <joint name="joint_5_2" type="revolute">
    <parent link="right_torso_1_1"/>
    <child link="right_torso_1_2"/>
    <origin rpy="0 0 0" xyz="0 0 4"/>
    <axis xyz="0 1 0"/>
    <dynamics damping="0.7" friction="0.0"/>
    <limit effort="30" lower="-2.2" upper="0.7" velocity="1.0"/>
    <safety_controller k_position="15" k_velocity="10" soft_lower_limit="-2.0" soft_upper_limit="0.5"/>
  </joint>
  <link name="right_torso_1_2">
    <collision>
      <origin rpy="0 0 0" xyz="0 0 4"/>
      <geometry>
        <cylinder length="4" radius="1"/>
      </geometry>
    </collision>
    <visual>
      <origin rpy="0 0 0" xyz="0 0 4"/>
      <geometry>
        <cylinder length="4" radius="1"/>
      </geometry>
      <material name="black"/>
    </visual>
    <inertial>
      <origin rpy="0 0 0" xyz="0 0 4"/>
      <mass value="1"/>
      <inertia ixx="3.5" ixy="0.0" ixz="0.0" iyy="3.5" iyz="0.0" izz="3.0"/>
    </inertial>
  </link>
  <joint name="joint_5_3" type="revolute">
    <parent link="right_torso_1_2"/>
    <child link="right_torso_1_3"/>
    <origin rpy="0 0 0" xyz="0 0 4"/>
    <axis xyz="0 1 0"/>
    <dynamics damping="0.7" friction="0.0"/>
    <limit effort="30" lower="-2.2" upper="0.7" velocity="1.0"/>
    <safety_controller k_position="15" k_velocity="10" soft_lower_limit="-2.0" soft_upper_limit="0.5"/>
  </joint>
  <link name="right_torso_1_3">
    <collision>
      <origin rpy="0 0 0" xyz="0 0 6"/>
      <geometry>
        <cylinder length="6" radius="1"/>
      </geometry>
    </collision>
    <visual>
      <origin rpy="0 0 0" xyz="0 0 6"/>
      <geometry>
        <cylinder length="6" radius="1"/>
      </geometry>
      <material name="black"/>
    </visual>
    <inertial>
      <origin rpy="0 0 0" xyz="0 0 6"/>
      <mass value="1"/>
      <inertia ixx="4.5" ixy="0.0" ixz="0.0" iyy="4.5" iyz="0.0" izz="3.0"/>
    </inertial>
  </link>
  <joint name="joint_6_1" type="revolute">
    <parent link="chassis"/>
    <child link="right_torso_2_1"/>
    <origin rpy="0 0 0" xyz="3.535 -3.535 4"/>
    <axis xyz="0 1 0"/>
    <dynamics damping="0.7" friction="0.0"/>
    <limit effort="30" lower="-2.2" upper="0.7" velocity="1.0"/>
    <safety_controller k_position="15" k_velocity="10" soft_lower_limit="-2.0" soft_upper_limit="0.5"/>
  </joint>
  <link name="right_torso_2_1">
    <collision>
      <origin rpy="0 0 0" xyz="0 0 4"/>
      <geometry>
        <cylinder length="4" radius="1"/>
      </geometry>
    </collision>
    <visual>
      <origin rpy="0 0 0" xyz="0 0 4"/>
      <geometry>
        <cylinder length="4" radius="1"/>
      </geometry>
      <material name="black"/>
    </visual>
    <inertial>
      <origin rpy="0 0 0" xyz="0 0 4"/>
      <mass value="1"/>
      <inertia ixx="3.5" ixy="0.0" ixz="0.0" iyy="3.5" iyz="0.0" izz="3.0"/>
    </inertial>
  </link>
  <joint name="joint_6_2" type="revolute">
    <parent link="right_torso_2_1"/>
    <child link="right_torso_2_2"/>
    <origin rpy="0 0 0" xyz="0 0 4"/>
    <axis xyz="0 1 0"/>
    <dynamics damping="0.7" friction="0.0"/>
    <limit effort="30" lower="-2.2" upper="0.7" velocity="1.0"/>
    <safety_controller k_position="15" k_velocity="10" soft_lower_limit="-2.0" soft_upper_limit="0.5"/>
  </joint>
  <link name="right_torso_2_2">
    <collision>
      <origin rpy="0 0 0" xyz="0 0 4"/>
      <geometry>
        <cylinder length="4" radius="1"/>
      </geometry>
    </collision>
    <visual>
      <origin rpy="0 0 0" xyz="0 0 4"/>
      <geometry>
        <cylinder length="4" radius="1"/>
      </geometry>
      <material name="black"/>
    </visual>
    <inertial>
      <origin rpy="0 0 0" xyz="0 0 4"/>
      <mass value="1"/>
      <inertia ixx="3.5" ixy="0.0" ixz="0.0" iyy="3.5" iyz="0.0" izz="3.0"/>
    </inertial>
  </link>
  <joint name="joint_6_3" type="revolute">
    <parent link="right_torso_2_2"/>
    <child link="right_torso_2_3"/>
    <origin rpy="0 0 0" xyz="0 0 4"/>
    <axis xyz="0 1 0"/>
    <dynamics damping="0.7" friction="0.0"/>
    <limit effort="30" lower="-2.2" upper="0.7" velocity="1.0"/>
    <safety_controller k_position="15" k_velocity="10" soft_lower_limit="-2.0" soft_upper_limit="0.5"/>
  </joint>
  <link name="right_torso_2_3">
    <collision>
      <origin rpy="0 0 0" xyz="0 0 6"/>
      <geometry>
        <cylinder length="6" radius="1"/>
      </geometry>
    </collision>
    <visual>
      <origin rpy="0 0 0" xyz="0 0 6"/>
      <geometry>
        <cylinder length="6" radius="1"/>
      </geometry>
      <material name="black"/>
    </visual>
    <inertial>
      <origin rpy="0 0 0" xyz="0 0 6"/>
      <mass value="1"/>
      <inertia ixx="4.5" ixy="0.0" ixz="0.0" iyy="4.5" iyz="0.0" izz="3.0"/>
    </inertial>
  </link>
  <joint name="joint_7_1" type="revolute">
    <parent link="chassis"/>
    <child link="right_torso_3_1"/>
    <origin rpy="0 0 0" xyz="5 0 4"/>
    <axis xyz="0 1 0"/>
    <dynamics damping="0.7" friction="0.0"/>
    <limit effort="30" lower="-2.2" upper="0.7" velocity="1.0"/>
    <safety_controller k_position="15" k_velocity="10" soft_lower_limit="-2.0" soft_upper_limit="0.5"/>
  </joint>
  <link name="right_torso_3_1">
    <collision>
      <origin rpy="0 0 0" xyz="0 0 4"/>
      <geometry>
        <cylinder length="4" radius="1"/>
      </geometry>
    </collision>
    <visual>
      <origin rpy="0 0 0" xyz="0 0 4"/>
      <geometry>
        <cylinder length="4" radius="1"/>
      </geometry>
      <material name="black"/>
    </visual>
    <inertial>
      <origin rpy="0 0 0" xyz="0 0 4"/>
      <mass value="1"/>
      <inertia ixx="3.5" ixy="0.0" ixz="0.0" iyy="3.5" iyz="0.0" izz="3.0"/>
    </inertial>
  </link>
  <joint name="joint_7_2" type="revolute">
    <parent link="right_torso_3_1"/>
    <child link="right_torso_3_2"/>
    <origin rpy="0 0 0" xyz="0 0 4"/>
    <axis xyz="0 1 0"/>
    <dynamics damping="0.7" friction="0.0"/>
    <limit effort="30" lower="-2.2" upper="0.7" velocity="1.0"/>
    <safety_controller k_position="15" k_velocity="10" soft_lower_limit="-2.0" soft_upper_limit="0.5"/>
  </joint>
  <link name="right_torso_3_2">
    <collision>
      <origin rpy="0 0 0" xyz="0 0 4"/>
      <geometry>
        <cylinder length="4" radius="1"/>
      </geometry>
    </collision>
    <visual>
      <origin rpy="0 0 0" xyz="0 0 4"/>
      <geometry>
        <cylinder length="4" radius="1"/>
      </geometry>
      <material name="black"/>
    </visual>
    <inertial>
      <origin rpy="0 0 0" xyz="0 0 4"/>
      <mass value="1"/>
      <inertia ixx="3.5" ixy="0.0" ixz="0.0" iyy="3.5" iyz="0.0" izz="3.0"/>
    </inertial>
  </link>
  <joint name="joint_7_3" type="revolute">
    <parent link="right_torso_3_2"/>
    <child link="right_torso_3_3"/>
    <origin rpy="0 0 0" xyz="0 0 4"/>
    <axis xyz="0 1 0"/>
    <dynamics damping="0.7" friction="0.0"/>
    <limit effort="30" lower="-2.2" upper="0.7" velocity="1.0"/>
    <safety_controller k_position="15" k_velocity="10" soft_lower_limit="-2.0" soft_upper_limit="0.5"/>
  </joint>
  <link name="right_torso_3_3">
    <collision>
      <origin rpy="0 0 0" xyz="0 0 6"/>
      <geometry>
        <cylinder length="6" radius="1"/>
      </geometry>
    </collision>
    <visual>
      <origin rpy="0 0 0" xyz="0 0 6"/>
      <geometry>
        <cylinder length="6" radius="1"/>
      </geometry>
      <material name="black"/>
    </visual>
    <inertial>
      <origin rpy="0 0 0" xyz="0 0 6"/>
      <mass value="1"/>
      <inertia ixx="4.5" ixy="0.0" ixz="0.0" iyy="4.5" iyz="0.0" izz="3.0"/>
    </inertial>
  </link>
  <joint name="joint_8_1" type="revolute">
    <parent link="chassis"/>
    <child link="right_torso_4_1"/>
    <origin rpy="0 0 0" xyz="3.535 3.535 4"/>
    <axis xyz="0 1 0"/>
    <dynamics damping="0.7" friction="0.0"/>
    <limit effort="30" lower="-2.2" upper="0.7" velocity="1.0"/>
    <safety_controller k_position="15" k_velocity="10" soft_lower_limit="-2.0" soft_upper_limit="0.5"/>
  </joint>
  <link name="right_torso_4_1">
    <collision>
      <origin rpy="0 0 0" xyz="0 0 4"/>
      <geometry>
        <cylinder length="4" radius="1"/>
      </geometry>
    </collision>
    <visual>
      <origin rpy="0 0 0" xyz="0 0 4"/>
      <geometry>
        <cylinder length="4" radius="1"/>
      </geometry>
      <material name="black"/>
    </visual>
    <inertial>
      <origin rpy="0 0 0" xyz="0 0 4"/>
      <mass value="1"/>
      <inertia ixx="3.5" ixy="0.0" ixz="0.0" iyy="3.5" iyz="0.0" izz="3.0"/>
    </inertial>
  </link>
  <joint name="joint_8_2" type="revolute">
    <parent link="right_torso_4_1"/>
    <child link="right_torso_4_2"/>
    <origin rpy="0 0 0" xyz="0 0 4"/>
    <axis xyz="0 1 0"/>
    <dynamics damping="0.7" friction="0.0"/>
    <limit effort="30" lower="-2.2" upper="0.7" velocity="1.0"/>
    <safety_controller k_position="15" k_velocity="10" soft_lower_limit="-2.0" soft_upper_limit="0.5"/>
  </joint>
  <link name="right_torso_4_2">
    <collision>
      <origin rpy="0 0 0" xyz="0 0 4"/>
      <geometry>
        <cylinder length="4" radius="1"/>
      </geometry>
    </collision>
    <visual>
      <origin rpy="0 0 0" xyz="0 0 4"/>
      <geometry>
        <cylinder length="4" radius="1"/>
      </geometry>
      <material name="black"/>
    </visual>
    <inertial>
      <origin rpy="0 0 0" xyz="0 0 4"/>
      <mass value="1"/>
      <inertia ixx="3.5" ixy="0.0" ixz="0.0" iyy="3.5" iyz="0.0" izz="3.0"/>
    </inertial>
  </link>
  <joint name="joint_8_3" type="revolute">
    <parent link="right_torso_4_2"/>
    <child link="right_torso_4_3"/>
    <origin rpy="0 0 0" xyz="0 0 4"/>
    <axis xyz="0 1 0"/>
    <dynamics damping="0.7" friction="0.0"/>
    <limit effort="30" lower="-2.2" upper="0.7" velocity="1.0"/>
    <safety_controller k_position="15" k_velocity="10" soft_lower_limit="-2.0" soft_upper_limit="0.5"/>
  </joint>
  <link name="right_torso_4_3">
    <collision>
      <origin rpy="0 0 0" xyz="0 0 6"/>
      <geometry>
        <cylinder length="6" radius="1"/>
      </geometry>
    </collision>
    <visual>
      <origin rpy="0 0 0" xyz="0 0 6"/>
      <geometry>
        <cylinder length="6" radius="1"/>
      </geometry>
      <material name="black"/>
    </visual>
    <inertial>
      <origin rpy="0 0 0" xyz="0 0 6"/>
      <mass value="1"/>
      <inertia ixx="4.5" ixy="0.0" ixz="0.0" iyy="4.5" iyz="0.0" izz="3.0"/>
    </inertial>
  </link>
  <transmission name="tran1_1">
    <type>transmission_interface/SimpleTransmission</type>
    <joint name="joint_1_1">
      <hardwareInterface>hardware_interface/EffortJointInterface</hardwareInterface>
    </joint>
    <actuator name="motor1_1">
      <hardwareInterface>hardware_interface/EffortJointInterface</hardwareInterface>
      <mechanicalReduction>1</mechanicalReduction>
    </actuator>
  </transmission>
  <transmission name="tran1_2">
    <type>transmission_interface/SimpleTransmission</type>
    <joint name="joint_1_2">
      <hardwareInterface>hardware_interface/EffortJointInterface</hardwareInterface>
    </joint>
    <actuator name="motor1_2">
      <hardwareInterface>hardware_interface/EffortJointInterface</hardwareInterface>
      <mechanicalReduction>1</mechanicalReduction>
    </actuator>
  </transmission>
  <transmission name="tran1_3">
    <type>transmission_interface/SimpleTransmission</type>
    <joint name="joint_1_3">
      <hardwareInterface>hardware_interface/EffortJointInterface</hardwareInterface>
    </joint>
    <actuator name="motor1_3">
      <hardwareInterface>hardware_interface/EffortJointInterface</hardwareInterface>
      <mechanicalReduction>1</mechanicalReduction>
    </actuator>
  </transmission>
  <transmission name="tran2_1">
    <type>transmission_interface/SimpleTransmission</type>
    <joint name="joint_2_1">
      <hardwareInterface>hardware_interface/EffortJointInterface</hardwareInterface>
    </joint>
    <actuator name="motor2_1">
      <hardwareInterface>hardware_interface/EffortJointInterface</hardwareInterface>
      <mechanicalReduction>1</mechanicalReduction>
    </actuator>
  </transmission>
  <transmission name="tran2_2">
    <type>transmission_interface/SimpleTransmission</type>
    <joint name="joint_2_2">
      <hardwareInterface>hardware_interface/EffortJointInterface</hardwareInterface>
    </joint>
    <actuator name="motor2_2">
      <hardwareInterface>hardware_interface/EffortJointInterface</hardwareInterface>
      <mechanicalReduction>1</mechanicalReduction>
    </actuator>
  </transmission>
  <transmission name="tran2_3">
    <type>transmission_interface/SimpleTransmission</type>
    <joint name="joint_2_3">
      <hardwareInterface>hardware_interface/EffortJointInterface</hardwareInterface>
    </joint>
    <actuator name="motor2_3">
      <hardwareInterface>hardware_interface/EffortJointInterface</hardwareInterface>
      <mechanicalReduction>1</mechanicalReduction>
    </actuator>
  </transmission>
  <transmission name="tran3_1">
    <type>transmission_interface/SimpleTransmission</type>
    <joint name="joint_3_1">
      <hardwareInterface>hardware_interface/EffortJointInterface</hardwareInterface>
    </joint>
    <actuator name="motor3_1">
      <hardwareInterface>hardware_interface/EffortJointInterface</hardwareInterface>
      <mechanicalReduction>1</mechanicalReduction>
    </actuator>
  </transmission>
  <transmission name="tran3_2">
    <type>transmission_interface/SimpleTransmission</type>
    <joint name="joint_3_2">
      <hardwareInterface>hardware_interface/EffortJointInterface</hardwareInterface>
    </joint>
    <actuator name="motor3_2">
      <hardwareInterface>hardware_interface/EffortJointInterface</hardwareInterface>
      <mechanicalReduction>1</mechanicalReduction>
    </actuator>
  </transmission>
  <transmission name="tran3_3">
    <type>transmission_interface/SimpleTransmission</type>
    <joint name="joint_3_3">
      <hardwareInterface>hardware_interface/EffortJointInterface</hardwareInterface>
    </joint>
    <actuator name="motor3_3">
      <hardwareInterface>hardware_interface/EffortJointInterface</hardwareInterface>
      <mechanicalReduction>1</mechanicalReduction>
    </actuator>
  </transmission>
  <transmission name="tran4_1">
    <type>transmission_interface/SimpleTransmission</type>
    <joint name="joint_4_1">
      <hardwareInterface>hardware_interface/EffortJointInterface</hardwareInterface>
    </joint>
    <actuator name="motor4_1">
      <hardwareInterface>hardware_interface/EffortJointInterface</hardwareInterface>
      <mechanicalReduction>1</mechanicalReduction>
    </actuator>
  </transmission>
  <transmission name="tran4_2">
    <type>transmission_interface/SimpleTransmission</type>
    <joint name="joint_4_2">
      <hardwareInterface>hardware_interface/EffortJointInterface</hardwareInterface>
    </joint>
    <actuator name="motor4_2">
      <hardwareInterface>hardware_interface/EffortJointInterface</hardwareInterface>
      <mechanicalReduction>1</mechanicalReduction>
    </actuator>
  </transmission>
  <transmission name="tran4_3">
    <type>transmission_interface/SimpleTransmission</type>
    <joint name="joint_4_3">
      <hardwareInterface>hardware_interface/EffortJointInterface</hardwareInterface>
    </joint>
    <actuator name="motor4_3">
      <hardwareInterface>hardware_interface/EffortJointInterface</hardwareInterface>
      <mechanicalReduction>1</mechanicalReduction>
    </actuator>
  </transmission>
  <transmission name="tran5_1">
    <type>transmission_interface/SimpleTransmission</type>
    <joint name="joint_5_1">
      <hardwareInterface>hardware_interface/EffortJointInterface</hardwareInterface>
    </joint>
    <actuator name="motor5_1">
      <hardwareInterface>hardware_interface/EffortJointInterface</hardwareInterface>
      <mechanicalReduction>1</mechanicalReduction>
    </actuator>
  </transmission>
  <transmission name="tran5_2">
    <type>transmission_interface/SimpleTransmission</type>
    <joint name="joint_5_2">
      <hardwareInterface>hardware_interface/EffortJointInterface</hardwareInterface>
    </joint>
    <actuator name="motor5_2">
      <hardwareInterface>hardware_interface/EffortJointInterface</hardwareInterface>
      <mechanicalReduction>1</mechanicalReduction>
    </actuator>
  </transmission>
  <transmission name="tran5_3">
    <type>transmission_interface/SimpleTransmission</type>
    <joint name="joint_5_3">
      <hardwareInterface>hardware_interface/EffortJointInterface</hardwareInterface>
    </joint>
    <actuator name="motor5_3">
      <hardwareInterface>hardware_interface/EffortJointInterface</hardwareInterface>
      <mechanicalReduction>1</mechanicalReduction>
    </actuator>
  </transmission>
  <transmission name="tran6_1">
    <type>transmission_interface/SimpleTransmission</type>
    <joint name="joint_6_1">
      <hardwareInterface>hardware_interface/EffortJointInterface</hardwareInterface>
    </joint>
    <actuator name="motor6_1">
      <hardwareInterface>hardware_interface/EffortJointInterface</hardwareInterface>
      <mechanicalReduction>1</mechanicalReduction>
    </actuator>
  </transmission>
  <transmission name="tran6_2">
    <type>transmission_interface/SimpleTransmission</type>
    <joint name="joint_6_2">
      <hardwareInterface>hardware_interface/EffortJointInterface</hardwareInterface>
    </joint>
    <actuator name="motor6_2">
      <hardwareInterface>hardware_interface/EffortJointInterface</hardwareInterface>
      <mechanicalReduction>1</mechanicalReduction>
    </actuator>
  </transmission>
  <transmission name="tran6_3">
    <type>transmission_interface/SimpleTransmission</type>
    <joint name="joint_6_3">
      <hardwareInterface>hardware_interface/EffortJointInterface</hardwareInterface>
    </joint>
    <actuator name="motor6_3">
      <hardwareInterface>hardware_interface/EffortJointInterface</hardwareInterface>
      <mechanicalReduction>1</mechanicalReduction>
    </actuator>
  </transmission>
  <transmission name="tran7_1">
    <type>transmission_interface/SimpleTransmission</type>
    <joint name="joint_7_1">
      <hardwareInterface>hardware_interface/EffortJointInterface</hardwareInterface>
    </joint>
    <actuator name="motor7_1">
      <hardwareInterface>hardware_interface/EffortJointInterface</hardwareInterface>
      <mechanicalReduction>1</mechanicalReduction>
    </actuator>
  </transmission>
  <transmission name="tran7_2">
    <type>transmission_interface/SimpleTransmission</type>
    <joint name="joint_7_2">
      <hardwareInterface>hardware_interface/EffortJointInterface</hardwareInterface>
    </joint>
    <actuator name="motor7_2">
      <hardwareInterface>hardware_interface/EffortJointInterface</hardwareInterface>
      <mechanicalReduction>1</mechanicalReduction>
    </actuator>
  </transmission>
  <transmission name="tran7_3">
    <type>transmission_interface/SimpleTransmission</type>
    <joint name="joint_7_3">
      <hardwareInterface>hardware_interface/EffortJointInterface</hardwareInterface>
    </joint>
    <actuator name="motor7_3">
      <hardwareInterface>hardware_interface/EffortJointInterface</hardwareInterface>
      <mechanicalReduction>1</mechanicalReduction>
    </actuator>
  </transmission>
  <transmission name="tran8_1">
    <type>transmission_interface/SimpleTransmission</type>
    <joint name="joint_8_1">
      <hardwareInterface>hardware_interface/EffortJointInterface</hardwareInterface>
    </joint>
    <actuator name="motor8_1">
      <hardwareInterface>hardware_interface/EffortJointInterface</hardwareInterface>
      <mechanicalReduction>1</mechanicalReduction>
    </actuator>
  </transmission>
  <transmission name="tran8_2">
    <type>transmission_interface/SimpleTransmission</type>
    <joint name="joint_8_2">
      <hardwareInterface>hardware_interface/EffortJointInterface</hardwareInterface>
    </joint>
    <actuator name="motor8_2">
      <hardwareInterface>hardware_interface/EffortJointInterface</hardwareInterface>
      <mechanicalReduction>1</mechanicalReduction>
    </actuator>
  </transmission>
  <transmission name="tran8_3">
    <type>transmission_interface/SimpleTransmission</type>
    <joint name="joint_8_3">
      <hardwareInterface>hardware_interface/EffortJointInterface</hardwareInterface>
    </joint>
    <actuator name="motor8_3">
      <hardwareInterface>hardware_interface/EffortJointInterface</hardwareInterface>
      <mechanicalReduction>1</mechanicalReduction>
    </actuator>
  </transmission>
</robot>

